Workbook

Sheet Data
A1: Фамилия | B1: Имя | C1: Отчество | D1: ФИО | E1: Место работы | F1: Должность | G1: Объем знаний | H1: Категория персонала | I1: Группа | J1: Дата проверки знаний | K1: Дата след проверки знаний | L1: Периодичность проверки знаний, лет | M1: отв рук-ль работ; | N1: производитель работ; | O1: опер. переговоры; | P1: опер.переключения; | Q1: в/в испытания; | R1: мех.испытания; | S1: вып. работ на высоте; | T1: Единоличный осмотр ЭУ; | U1: оперативного персонала; | V1: инспектирования; | W1: выдача нарядов-допусков и распоряжений; | X1: пусто; | Y1: пусто; | Z1: наблюдающий; | AA1: допускающий; | AB1: член бригады; | AC1: работа на высоте; | AD1: пусто; | AE1: пусто; | AF1: пусто; | AG1: пусто; | AH1: работа под напряжением; | AI1: ограждение места работ; | AJ1: электросварочные работы; | AK1: с мегомметром; | AL1: вальщик леса; | AM1: стропальщик; | AN1: фазировка кабельных линий; | AO1: прокол кабеля для ЛИК; | AP1: водитель;
A2: Иванов | B2: Алексей | C2: Иванович | D2: =Data!$A2&" "&Data!$B2&" "&Data!$C2 -> Иванов Алексей Иванович | E2: ЭЧ-11 | F2: ведущий инженер | G2: ЭЧТ | H2: Административно-технического | I2: V | J2: 45953 | K2: 47049 | L2: 3
A3: Петров | B3: Дмитрий | C3: Петрович | D3: =Data!$A3&" "&Data!$B3&" "&Data!$C3 -> Петров Дмитрий Петрович | E3: ЭЧ-3 | F3: ведущий инженер | G3: ЭЧТ | H3: Административно-технического | I3: V | J3: 45651 | K3: 46746 | L3: 3
A4: Сидоров | B4: Сергей | C4: Сергеевич | D4: =Data!$A4&" "&Data!$B4&" "&Data!$C4 -> Сидоров Сергей Сергеевич | E4: ЭЧ-2 | F4: Ведущий инженер по эксплуатации технических средств | G4: ЭЧТ | H4: Административно-технического | I4: V | J4: 46084 | K4: 47180 | L4: 3 | T4: 1
A5: Козлов | B5: Андрей | C5: Андреевич | D5: =Data!$A5&" "&Data!$B5&" "&Data!$C5 -> Козлов Андрей Андреевич | E5: ЭЧ-6 | F5: Ведущий инженер по эксплуатации технических средств | G5: ЭЧТ | H5: Административно-технического | I5: V | J5: 45729 | K5: 46831 | L5: 3 | T5: 1
A6: Новиков | B6: Иван | C6: Николаевич | D6: =Data!$A6&" "&Data!$B6&" "&Data!$C6 -> Новиков Иван Николаевич | E6: ЭЧ-8 | F6: Ведущий инженер по эксплуатации технических средств | G6: ЭЧТ | H6: Административно-технического | I6: V | J6: 45370 | K6: 46465 | L6: 3
A7: Морозов | B7: Михаил | C7: Владимирович | D7: =Data!$A7&" "&Data!$B7&" "&Data!$C7 -> Морозов Михаил Владимирович | E7: ЭЧ-15 | F7: Ведущий инженер технического отдела | G7: ЭЧТ | H7: Административно-технического | I7: V | J7: 45603 | K7: 46333 | L7: 3 | T7: 1
A8: Соколов | B8: Николай | C8: Александрович | D8: =Data!$A8&" "&Data!$B8&" "&Data!$C8 -> Соколов Николай Александрович | E8: НТЭ | F8: Ведущий специалист по охране труда | G8: Эчот | H8: Инспектирующего | I8: V | J8: 45806 | K8: 46902 | L8: 3
A9: Лебедев | B9: Владимир | C9: Павлович | D9: =Data!$A9&" "&Data!$B9&" "&Data!$C9 -> Лебедев Владимир Павлович | E9: ТЦЭ | F9: Ведущий специалист по охране труда | G9: Эчот | H9: Инспектирующего | I9: V | J9: 45377 | K9: 46474 | L9: 3
A10: Попов | B10: Артём | C10: Борисович | D10: =Data!$A10&" "&Data!$B10&" "&Data!$C10 -> Попов Артём Борисович | E10: ЭЧ-1 | F10: Ведущий специалист по охране труда | G10: Эчот | H10: Инспектирующего | I10: V | J10: 44826 | K10: 45922 | L10: 3
A11: Волков | B11: Павел | C11: Геннадьевич | D11: =Data!$A11&" "&Data!$B11&" "&Data!$C11 -> Волков Павел Геннадьевич | E11: ЭЧ-10 | F11: ведущий специалист по охране труда | G11: Эчот | H11: Инспектирующего | I11: V | J11: 45013 | K11: 46109 | L11: 3
A12: Фёдоров | B12: Игорь | C12: Евгеньевич | D12: =Data!$A12&" "&Data!$B12&" "&Data!$C12 -> Фёдоров Игорь Евгеньевич | E12: ЭЧ-10 | F12: Ведущий специалист по охране труда | G12: Эчот | H12: Инспектирующего | I12: V | J12: 45447 | K12: 46542 | L12: 3
A13: Алексеев | B13: Виктор | C13: Денисович | D13: =Data!$A13&" "&Data!$B13&" "&Data!$C13 -> Алексеев Виктор Денисович | E13: ЭЧ-15 | F13: Ведущий специалист по охране труда | G13: Эчот | H13: Инспектирующего | I13: V | J13: 44986 | K13: 47182 | L13: 3
A14: Михайлов | B14: Олег | C14: Олегович | D14: =Data!$A14&" "&Data!$B14&" "&Data!$C14 -> Михайлов Олег Олегович | E14: ЭЧ-2 | F14: Ведущий специалист по охране труда | G14: Эчот | H14: Инспектирующего | I14: V | J14: 45818 | K14: 47116 | L14: 3 | V14: 1
A15: Зайцев | B15: Юрий | C15: Юрьевич | D15: =Data!$A15&" "&Data!$B15&" "&Data!$C15 -> Зайцев Юрий Юрьевич | E15: ЭЧ-3 | F15: Ведущий специалист по охране труда | G15: Эчот | H15: Инспектирующего | I15: V | J15: 45369 | K15: 46464 | L15: 3 | V15: 1
A16: Белов | B16: Борис | C16: Михайлович | D16: =Data!$A16&" "&Data!$B16&" "&Data!$C16 -> Белов Борис Михайлович | E16: ЭЧ-4 | F16: Ведущий специалист по охране труда | G16: Эчот | H16: Инспектирующего | I16: V | J16: 45369 | K16: 46464 | L16: 3 | V16: 1
A17: Васильев | B17: Геннадий | C17: Алексеевич | D17: =Data!$A17&" "&Data!$B17&" "&Data!$C17 -> Васильев Геннадий Алексеевич | E17: ЭЧ-8 | F17: Ведущий специалист по охране труда | G17: Эчот | H17: Инспектирующего | I17: V | J17: 45811 | K17: 46907 | L17: 3
A18: Егоров | B18: Георгий | C18: Викторович | D18: =Data!$A18&" "&Data!$B18&" "&Data!$C18 -> Егоров Георгий Викторович | E18: ТЦЭ | F18: Главный инженер | G18: ЭЧГ | H18: Административно-технического | I18: V | J18: 45525 | K18: 45890 | L18: 1
A19: Орлов | B19: Денис | C19: Григорьевич | D19: =Data!$A19&" "&Data!$B19&" "&Data!$C19 -> Орлов Денис Григорьевич | E19: ЭЧ-1 | F19: Главный инженер | G19: ЭЧГ | H19: Административно-технического | I19: V | J19: 46084 | K19: 46449 | L19: 1 | M19: 1 | T19: 1
A20: Тихонов | B20: Евгений | C20: Игоревич | D20: =Data!$A20&" "&Data!$B20&" "&Data!$C20 -> Тихонов Евгений Игоревич | E20: ЭЧ-10 | F20: Главный инженер | G20: ЭЧГ | H20: Административно-технического | I20: V | J20: 45957 | K20: 46322 | L20: 1 | M20: 1 | Q20: 1 | T20: 1
A21: Баранов | B21: Захар | C21: Фёдорович | D21: =Data!$A21&" "&Data!$B21&" "&Data!$C21 -> Баранов Захар Фёдорович | E21: ЭЧ-11 | F21: Главный инженер | G21: ЭЧГ | H21: Административно-технического | I21: V | J21: 46085 | K21: 46450 | L21: 1 | M21: 1 | Q21: 1 | T21: 1
A22: Кузнецов | B22: Алексей | C22: Иванович | D22: =Data!$A22&" "&Data!$B22&" "&Data!$C22 -> Кузнецов Алексей Иванович | E22: ЭЧ-12 | F22: Главный инженер | G22: ЭЧГ | H22: Административно-технического | I22: V | J22: 45811 | K22: 46542 | L22: 1 | M22: 1 | Q22: 1 | T22: 1
A23: Давыдов | B23: Дмитрий | C23: Петрович | D23: =Data!$A23&" "&Data!$B23&" "&Data!$C23 -> Давыдов Дмитрий Петрович | E23: ЭЧ-13 | F23: Главный инженер | G23: ЭЧГ | H23: Административно-технического | I23: V | J23: 45541 | K23: 46295 | L23: 1 | M23: 1 | Q23: 1 | T23: 1 | AP23: 1
A24: Богданов | B24: Сергей | C24: Сергеевич | D24: =Data!$A24&" "&Data!$B24&" "&Data!$C24 -> Богданов Сергей Сергеевич | E24: ЭЧ-14 | F24: Главный инженер | G24: ЭЧГ | H24: Административно-технического | I24: V | J24: 45538 | K24: 46255 | L24: 1 | M24: 1 | T24: 1
A25: Семёнов | B25: Андрей | C25: Андреевич | D25: =Data!$A25&" "&Data!$B25&" "&Data!$C25 -> Семёнов Андрей Андреевич | E25: ЭЧ-15 | F25: Главный инженер | G25: ЭЧГ | H25: Административно-технического | I25: V | J25: 45526 | K25: 46270 | L25: 1 | M25: 1 | Q25: 1 | T25: 1
A26: Осипов | B26: Иван | C26: Николаевич | D26: =Data!$A26&" "&Data!$B26&" "&Data!$C26 -> Осипов Иван Николаевич | E26: ЭЧ-16 | F26: Главный инженер | G26: ЭЧГ | H26: Административно-технического | I26: V | J26: 45651 | K26: 46372 | L26: 1 | T26: 1
A27: Савельев | B27: Михаил | C27: Владимирович | D27: =Data!$A27&" "&Data!$B27&" "&Data!$C27 -> Савельев Михаил Владимирович | E27: ЭЧ-19 | F27: Главный инженер | G27: ЭЧГ | H27: Административно-технического | I27: V | J27: 45736 | K27: 46456 | L27: 1 | M27: 1 | Q27: 1 | T27: 1
A28: Тимофеев | B28: Николай | C28: Александрович | D28: =Data!$A28&" "&Data!$B28&" "&Data!$C28 -> Тимофеев Николай Александрович | E28: ЭЧ-2 | F28: Главный инженер | G28: ЭЧГ | H28: Административно-технического | I28: V | J28: 45898 | K28: 46263 | L28: 1 | M28: 1 | T28: 1
A29: Медведев | B29: Владимир | C29: Павлович | D29: =Data!$A29&" "&Data!$B29&" "&Data!$C29 -> Медведев Владимир Павлович | E29: ЭЧ-21 | F29: Главный инженер | G29: ЭЧГ | H29: Административно-технического | I29: V | J29: 46092 | K29: 46457 | L29: 1 | M29: 1 | Q29: 1 | T29: 1
A30: Андреев | B30: Артём | C30: Борисович | D30: =Data!$A30&" "&Data!$B30&" "&Data!$C30 -> Андреев Артём Борисович | E30: ЭЧ-24 | F30: Главный инженер | G30: ЭЧГ | H30: Административно-технического | I30: V | J30: 46087 | K30: 46452 | L30: 1 | M30: 1 | Q30: 1 | T30: 1
A31: Макаров | B31: Павел | C31: Геннадьевич | D31: =Data!$A31&" "&Data!$B31&" "&Data!$C31 -> Макаров Павел Геннадьевич | E31: ЭЧ-3 | F31: Главный инженер | G31: ЭЧГ | H31: Административно-технического | I31: V | J31: 45950 | K31: 46315 | L31: 1 | M31: 1 | T31: 1
A32: Иванов2 | B32: Игорь | C32: Евгеньевич | D32: =Data!$A32&" "&Data!$B32&" "&Data!$C32 -> Иванов2 Игорь Евгеньевич | E32: ЭЧ-4 | F32: Главный инженер | G32: ЭЧГ | H32: Административно-технического | I32: V | J32: 45734 | K32: 46463 | L32: 1 | M32: 1 | T32: 1
A33: Петров2 | B33: Виктор | C33: Денисович | D33: =Data!$A33&" "&Data!$B33&" "&Data!$C33 -> Петров2 Виктор Денисович | E33: ЭЧ-6 | F33: Главный инженер | G33: ЭЧГ | H33: Административно-технического | I33: V | J33: 45162 | K33: 45528 | L33: 1 | M33: 1 | Q33: 1 | T33: 1
A34: Сидоров2 | B34: Олег | C34: Олегович | D34: =Data!$A34&" "&Data!$B34&" "&Data!$C34 -> Сидоров2 Олег Олегович | E34: ЭЧ-7 | F34: Главный инженер | G34: ЭЧГ | H34: Административно-технического | I34: V | J34: 46087 | K34: 46452 | L34: 1 | M34: 1 | T34: 1
A35: Козлов2 | B35: Юрий | C35: Юрьевич | D35: =Data!$A35&" "&Data!$B35&" "&Data!$C35 -> Козлов2 Юрий Юрьевич | E35: ЭЧ-8 | F35: Главный инженер | G35: ЭЧГ | H35: Административно-технического | I35: V | J35: 45651 | K35: 46381 | L35: 1 | M35: 1 | T35: 1
A36: Новиков2 | B36: Борис | C36: Михайлович | D36: =Data!$A36&" "&Data!$B36&" "&Data!$C36 -> Новиков2 Борис Михайлович | E36: ЭЧ-9 | F36: Главный инженер | G36: ЭЧГ | H36: Административно-технического | I36: V | J36: 46086 | K36: 46451 | L36: 1 | M36: 1 | Q36: 1 | T36: 1
A37: Морозов2 | B37: Геннадий | C37: Алексеевич | D37: =Data!$A37&" "&Data!$B37&" "&Data!$C37 -> Морозов2 Геннадий Алексеевич | E37: ЭЧ-16 | F37: заместитель начальника | G37: ЭЧЗэ | H37: Административно-технического | I37: V | J37: 46111 | K37: 46476 | L37: 1 | M37: 1 | T37: 1
A38: Соколов2 | B38: Георгий | C38: Викторович | D38: =Data!$A38&" "&Data!$B38&" "&Data!$C38 -> Соколов2 Георгий Викторович | E38: ТЦЭ | F38: заместитель начальника | G38: ЭЧЗэ | H38: Административно-технического | I38: V | J38: 45946 | K38: 46311 | L38: 1
A39: Лебедев2 | B39: Денис | C39: Григорьевич | D39: =Data!$A39&" "&Data!$B39&" "&Data!$C39 -> Лебедев2 Денис Григорьевич | E39: ТЦЭ | F39: заместитель начальника | G39: ЭЧЗэ | H39: Административно-технического | I39: V | J39: 45947 | K39: 46312 | L39: 1
A40: Попов2 | B40: Евгений | C40: Игоревич | D40: =Data!$A40&" "&Data!$B40&" "&Data!$C40 -> Попов2 Евгений Игоревич | E40: ЭЧ-1 | F40: заместитель начальника | G40: ЭЧЗк | H40: Административно-технического | I40: V | J40: 45946 | K40: 46311 | L40: 1 | M40: 1 | Q40: 1 | T40: 1
...

Sheet Input
A2: ЭЧ-11 | B2: Дистанция электроснабжения №11
A3: ЭЧ-3 | B3: Панковская дистанция электроснабжения
A4: ЭЧ-2 | B4: Дистанция электроснабжения №2
A5: ЭЧ-6 | B5: Дистанция электроснабжения №6
A6: ЭЧ-8 | B6: Дистанция электроснабжения №8
A7: ЭЧ-7 | B7: Покровско-Стрешневская дистанция электроснабжения
A8: ЭЧ-9 | B8: Дистанция электроснабжения №9
A9: ЭЧ-12 | B9: Дистанция электроснабжения №12
A10: ЭЧ-14 | B10: Дистанция электроснабжения №14
A11: ЭЧ-15 | B11: Дистанция электроснабжения №15
A12: ЭЧ-21 | B12: Дистанция электроснабжения №21
A13: ЭЧ-24 | B13: Дистанция электроснабжения №24
... A15: ТЦЭ | B15: Тяговая ЦЭ
D16: Очередная проверка
D17: Внеочередная проверка
D18: Первичная проверка
F19: Петров Дмитрий Петрович | G19: НТЭГ
F20: Козлов Андрей Андреевич | G20: НТЭЗ-1
F21: Новиков Иван Николаевич | G21: НТЭК
I22: Сидоров Сергей Сергеевич | J22: НТЭТ
I23: Морозов Михаил Владимирович | J23: НТЭК
I24: Михайлов Олег Олегович | J24: НТЭТех
I25: Зайцев Юрий Юрьевич | J25: НТЭЗ-1
L26: ЭЧГ | M26: Правила по охране труда, ПТЭЭП, инструкции по электробезопасности для руководящего состава
L27: ЭЧ | M27: Комплект нормативных документов и инструкций для персонала дистанции электроснабжения
L28: ЭЧТ | M28: Правила устройства электроустановок, техническая эксплуатация, охрана труда, пожарная безопасность
L29: Эчот | M29: Нормативные документы по охране труда, пожарной безопасности и локальные инструкции
L30: ЭЧЗк | M30: Инструкции по контактной сети, охране труда и безопасному производству работ
L31: ЭЧЗэ | M31: Инструкции по тяговым подстанциям, охране труда и безопасному производству работ
